<?xml version="1.0"?>

<robot xmlns:xacro="http://www.ros.org/wiki/xacro">

  <xacro:macro name="open_manipulator_x" params="prefix=''">

    <xacro:property
      name="meshes_file_direction"
      value="package://open_manipulator_x_description/meshes"/>

    <link name="${prefix}link1">
      <visual>
        <origin xyz="0 0 0" rpy="0 0 0"/>
        <geometry>
          <mesh filename="${meshes_file_direction}/link1.stl" scale="0.001 0.001 0.001"/>
        </geometry>
        <material name="grey"/>
      </visual>
      <collision>
        <origin xyz="0 0 0" rpy="0 0 0"/>
        <geometry>
          <mesh filename="${meshes_file_direction}/link1.stl" scale="0.001 0.001 0.001"/>
        </geometry>
      </collision>
      <inertial>
        <origin xyz="3.0876154e-04 0.0000000e+00 -1.2176461e-04"/>
        <mass value="7.9119962e-02"/>
        <inertia ixx="1.2505234e-05" ixy="0.0" ixz="-1.7855208e-07"
                 iyy="2.1898364e-05" iyz="0.0"
                 izz="1.9267361e-05"/>
      </inertial>
    </link>

    <joint name="${prefix}joint1" type="revolute">
      <parent link="${prefix}link1"/>
      <child link="${prefix}link2"/>
      <origin xyz="0.012 0.0 0.017" rpy="0 0 0"/>
      <axis xyz="0 0 1"/>
      <limit effort="5" lower="${-pi}" upper="${pi}" velocity="10"/>
      <dynamics damping="0.1"/>
    </joint>

    <link name="${prefix}link2">
      <visual>
        <origin xyz="0 0 0.019" rpy="0 0 0"/>
        <geometry>
          <mesh filename="${meshes_file_direction}/link2.stl" scale="0.001 0.001 0.001"/>
        </geometry>
        <material name="grey"/>
      </visual>
      <collision>
        <origin xyz="0 0 0.019" rpy="0 0 0"/>
        <geometry>
          <mesh filename="${meshes_file_direction}/link2.stl" scale="0.001 0.001 0.001"/>
        </geometry>
      </collision>
      <inertial>
        <origin xyz="-3.0184870e-04 5.4043684e-04 0.047433463999999995"/>
        <mass value="9.8406837e-03"/>
        <inertia ixx="3.4543422e-05" ixy="-1.6031095e-08" ixz="-3.8375155e-07"
                 iyy="3.2689329e-05" iyz="2.8511935e-08"
                 izz="1.8850320e-05"/>
      </inertial>
    </link>

    <joint name="${prefix}joint2" type="revolute">
      <parent link="${prefix}link2"/>
      <child link="${prefix}link3"/>
      <origin xyz="0.0 0.0 0.0595" rpy="0 0 0"/>
      <axis xyz="0 1 0"/>
      <limit effort="10" lower="-1.5" upper="1.5" velocity="4.8"/>
      <dynamics damping="0.1"/>
    </joint>

    <link name="${prefix}link3">
      <visual>
        <origin xyz="0 0 0" rpy="0 -1.57 0"/>
        <geometry>
          <mesh filename="${meshes_file_direction}/link4.stl" scale="0.001 0.001 0.001"/>
        </geometry>
        <material name="grey"/>
      </visual>
      <collision>
        <origin xyz="0 0 0" rpy="0 -1.57 0"/>
        <geometry>
          <mesh filename="${meshes_file_direction}/link4.stl" scale="0.001 0.001 0.001"/>
        </geometry>
      </collision>
      <inertial>
        <origin xyz="1.0308393e-02 3.7743363e-04 1.0170197e-01"/>
        <mass value="1.3850917e-02"/>
        <inertia ixx="3.3055381e-04" ixy="-9.7940978e-08" ixz="-3.8505711e-05"
                 iyy="3.4290447e-04" iyz="-1.5717516e-06"
                 izz="6.0346498e-05"/>
      </inertial>
    </link>

    <joint name="${prefix}joint3" type="revolute">
      <parent link="${prefix}link3"/>
      <child link="${prefix}link4"/>
      <origin xyz="0.0 0 0.128" rpy="0 0 0"/>
      <axis xyz="0 1 0"/>
      <limit effort="10" lower="-1.5" upper="1.4" velocity="4.8"/>
      <dynamics damping="0.1"/>
    </joint>

    <link name="${prefix}link4">
      <visual>
        <origin xyz="0 0 0" rpy="3.14 -1.57 0"/>
        <geometry>
          <mesh filename="${meshes_file_direction}/link3.stl" scale="0.001 0.001 0.001"/>
        </geometry>
        <material name="grey"/>
      </visual>
      <collision>
        <origin xyz="0 0 0" rpy="3.14 -1.57 0"/>
        <geometry>
          <mesh filename="${meshes_file_direction}/link3.stl" scale="0.001 0.001 0.001"/>
        </geometry>
      </collision>
      <inertial>
        <origin xyz="9.0909590e-02 3.8929816e-04 2.2413279e-04"/>
        <mass value="1.3274562e-02"/>
        <inertia ixx="3.0654178e-05" ixy="-1.2764155e-06" ixz="-2.6874417e-07"
                 iyy="2.4230292e-04" iyz="1.1559550e-08"
                 izz="2.5155057e-04"/>
      </inertial>
    </link>

    <joint name="${prefix}joint4" type="revolute">
      <parent link="${prefix}link4"/>
      <child link="${prefix}link5"/>
      <origin xyz="0.127 0.0 0.024" rpy="0 0 0"/>
      <axis xyz="0 1 0"/>
      <limit effort="10" lower="-0.16" upper="1.97" velocity="4.8"/>
      <dynamics damping="0.1"/>
    </joint>

    <link name="${prefix}link5">
      <visual>
        <origin xyz="0 0 0" rpy="0 0 0"/>
        <geometry>
          <mesh filename="${meshes_file_direction}/link5.stl" scale="0.001 0.001 0.001"/>
        </geometry>
        <material name="grey"/>
      </visual>
      <collision>
        <origin xyz="0 0 0" rpy="0 0 0"/>
        <geometry>
          <mesh filename="${meshes_file_direction}/link5.stl" scale="0.001 0.001 0.001"/>
        </geometry>
      </collision>
      <inertial>
        <origin xyz="4.4206755e-02 3.6839985e-07 8.9142216e-03"/>
        <mass value="1.4327573e-02"/>
        <inertia ixx="8.0870749e-05" ixy="0.0" ixz="-1.0157896e-06"
                 iyy="7.5980465e-05" iyz="0.0"
                 izz="9.3127351e-05"/>
      </inertial>
    </link>

    <joint name="${prefix}joint5" type="revolute">
      <parent link="${prefix}link5"/>
      <child link="${prefix}end_effector_mount_link"/>
      <origin xyz="0.168 0.0005 0.0" rpy="0 0 0"/>
      <axis xyz="1 0 0"/>
      <limit effort="1.0" lower="0" upper="0" velocity="1.0"/>
    </joint>

    <link name="${prefix}end_effector_mount_link">
      <inertial>
        <origin xyz="0 0 0" rpy="0 0 0"/>
        <mass value="0.0237"/>
        <inertia ixx="0.000354094" ixy="-0.000001193" ixz="-0.000002445"
                 iyy="0.000260915" iyz="-0.000002905"
                 izz="0.000529257"/>
      </inertial>
    </link>

    <joint name="${prefix}end_effector_joint" type="fixed">
      <parent link="${prefix}end_effector_mount_link"/>
      <child link="${prefix}end_effector_link"/>
      <origin xyz="0 0 0" rpy="0 0 0"/>
    </joint>

    <link name="${prefix}end_effector_link">
      <visual>
        <origin xyz="0 0 0" rpy="0 0 0"/>
        <geometry>
          <box size="0.01 0.01 0.01"/>
        </geometry>
        <material name="red"/>
      </visual>
      <collision>
        <origin xyz="0 0 0" rpy="0 0 0"/>
        <geometry>
          <box size="0.01 0.01 0.01"/>
        </geometry>
      </collision>
      <inertial>
        <origin xyz="0 0 0" rpy="0 0 0"/>
        <mass value="0.001"/>
        <inertia ixx="1.0e-06" ixy="0.0" ixz="0.0"
                 iyy="1.0e-06" iyz="0.0"
                 izz="1.0e-06"/>
      </inertial>
    </link>

  </xacro:macro>

</robot>
